<?xml version="1.0"?>

<robot name="robot model">

  <link name="base_footprint"/>

  <link name="base_link">
     <visual>
      <geometry>
        <box size="0.5 0.3 0.1"/>
      </geometry>
      <material name="blue">
        <color rgba="0 0 1 1"/>
      </material>
      <origin xyz="0 0 0" rpy="0 0 0" />
    </visual>
  </link>

  <joint name="base_footprint_to_base_link" type="fixed">
    <parent link="base_footprint"/>
    <child link="base_link"/>
    <origin xyz="0 0 0.0" rpy="0 0 0"/>
    <limit effort="100" velocity="100" lower="-100" upper="100"/>
  </joint>

  <link name="left_wheel">
    <visual>
      <geometry>
        <cylinder length="0.05" radius="0.1"/>
      </geometry>
      <material name="black">
        <color rgba="0 1 0 1"/>
      </material>
    </visual>
  </link>

  <link name="right_wheel">
    <visual>
      <geometry>
        <cylinder length="0.05" radius="0.1"/>
      </geometry>
      <material name="black">
        <color rgba="0 1 0 1"/>
      </material>
    </visual>
  </link>

  <joint name="base_to_left_wheel" type="continuous">
    <parent link="base_link"/>
    <child link="left_wheel"/>
    <origin xyz="0 0.15 0" rpy="-1.57 0 0"/>
    <axis xyz="0 1 0"/>
  </joint>

  <joint name="base_to_right_wheel" type="continuous">
    <parent link="base_link"/>
    <child link="right_wheel"/>
    <origin xyz="0 -0.15 0" rpy="-1.57 0 0"/>
    <axis xyz="0 1 0"/>
  </joint>

</robot>