<?xml version="1.0"?>
<robot name="triangle_bot">
  <!-- Base plate -->
  <link name="base_link">
    <visual>
      <geometry>
         <mesh filename="./SeBot.stl" scale="1 1 1"/>
      </geometry>
      <origin xyz="0 0 0.005" rpy="0 1.5708 0"/>
      <material name="grey">
        <color rgba="0.6 0.6 0.6 1.0"/>
      </material>
    </visual>
    <collision>
      <geometry>
        <box size="0.3 0.3 0.01"/>
      </geometry>
    </collision>
    <inertial>
      <mass value="1.0"/>
      <inertia ixx="0.01" ixy="0.0" ixz="0.0"
               iyy="0.01" iyz="0.0"
               izz="0.01"/>
    </inertial>
  </link>

  <!-- Left wheel -->
  <link name="left_wheel">
    <visual>
      <geometry>
        <cylinder radius="0.035" length="0.02"/>
      </geometry>
      <origin xyz="0 0.12 0.035" rpy="1.5708 0 0"/>
      <material name="black">
        <color rgba="0.1 0.1 0.1 1"/>
      </material>
    </visual>
  </link>

  <joint name="left_wheel_joint" type="continuous">
    <parent link="base_link"/>
    <child link="left_wheel"/>
    <origin xyz="0 0.12 0.035" rpy="0 0 0"/>
    <axis xyz="0 1 0"/>
  </joint>

  <!-- Right wheel -->
  <link name="right_wheel">
    <visual>
      <geometry>
        <cylinder radius="0.035" length="0.02"/>
      </geometry>
      <origin xyz="0 -0.12 0.035" rpy="1.5708 0 0"/>
      <material name="black"/>
    </visual>
  </link>

  <joint name="right_wheel_joint" type="continuous">
    <parent link="base_link"/>
    <child link="right_wheel"/>
    <origin xyz="0 -0.12 0.035" rpy="0 0 0"/>
    <axis xyz="0 1 0"/>
  </joint>

  <!-- Left motor -->
  <link name="left_motor">
    <visual>
      <geometry>
        <cylinder radius="0.02" length="0.04"/>
      </geometry>
      <origin xyz="0.02 0.12 0.035" rpy="1.5708 0 0"/>
      <material name="blue">
        <color rgba="0 0 1 1"/>
      </material>
    </visual>
  </link>

  <joint name="left_motor_joint" type="fixed">
    <parent link="base_link"/>
    <child link="left_motor"/>
    <origin xyz="0.02 0.12 0.035" rpy="0 0 0"/>
  </joint>

  <!-- Right motor -->
  <link name="right_motor">
    <visual>
      <geometry>
        <cylinder radius="0.02" length="0.04"/>
      </geometry>
      <origin xyz="0.02 -0.12 0.035" rpy="1.5708 0 0"/>
      <material name="blue"/>
    </visual>
  </link>

  <joint name="right_motor_joint" type="fixed">
    <parent link="base_link"/>
    <child link="right_motor"/>
    <origin xyz="0.02 -0.12 0.035" rpy="0 0 0"/>
  </joint>

  <!-- Caster wheel -->
  <link name="caster_wheel">
    <visual>
      <geometry>
        <sphere radius="0.015"/>
      </geometry>
      <origin xyz="0.15 0 0.015" rpy="0 0 0"/>
      <material name="grey"/>
    </visual>
  </link>

  <joint name="caster_joint" type="continuous">
    <parent link="base_link"/>
    <child link="caster_wheel"/>
    <origin xyz="0.15 0 0.015" rpy="0 0 0"/>
    <axis xyz="0 0 1"/>
  </joint>

</robot>